[2022-05-30 11:01:24,551] {taskinstance.py:903} INFO - Dependencies all met for <TaskInstance: create_table_dag.create_tables 2022-05-30T11:01:23.779712+00:00 [queued]>
[2022-05-30 11:01:24,563] {taskinstance.py:903} INFO - Dependencies all met for <TaskInstance: create_table_dag.create_tables 2022-05-30T11:01:23.779712+00:00 [queued]>
[2022-05-30 11:01:24,564] {taskinstance.py:1095} INFO - 
--------------------------------------------------------------------------------
[2022-05-30 11:01:24,564] {taskinstance.py:1096} INFO - Starting attempt 1 of 4
[2022-05-30 11:01:24,564] {taskinstance.py:1097} INFO - 
--------------------------------------------------------------------------------
[2022-05-30 11:01:24,572] {taskinstance.py:1115} INFO - Executing <Task(PythonOperator): create_tables> on 2022-05-30T11:01:23.779712+00:00
[2022-05-30 11:01:24,575] {standard_task_runner.py:52} INFO - Started process 1226 to run task
[2022-05-30 11:01:24,577] {standard_task_runner.py:76} INFO - Running: ['***', 'tasks', 'run', 'create_table_dag', 'create_tables', '2022-05-30T11:01:23.779712+00:00', '--job-id', '11', '--pool', 'default_pool', '--raw', '--subdir', 'DAGS_FOLDER/create_tables_dag.py', '--cfg-path', '/tmp/tmpb41yv9j6', '--error-file', '/tmp/tmpot387862']
[2022-05-30 11:01:24,579] {standard_task_runner.py:77} INFO - Job 11: Subtask create_tables
[2022-05-30 11:01:24,606] {logging_mixin.py:109} INFO - Running <TaskInstance: create_table_dag.create_tables 2022-05-30T11:01:23.779712+00:00 [running]> on host 1367f8687ad2
[2022-05-30 11:01:24,637] {taskinstance.py:1254} INFO - Exporting the following env vars:
AIRFLOW_CTX_DAG_OWNER=kirill
AIRFLOW_CTX_DAG_ID=create_table_dag
AIRFLOW_CTX_TASK_ID=create_tables
AIRFLOW_CTX_EXECUTION_DATE=2022-05-30T11:01:23.779712+00:00
AIRFLOW_CTX_DAG_RUN_ID=manual__2022-05-30T11:01:23.779712+00:00
[2022-05-30 11:01:24,639] {taskinstance.py:1463} ERROR - Task failed with exception
Traceback (most recent call last):
  File "/home/airflow/.local/lib/python3.6/site-packages/airflow/models/taskinstance.py", line 1165, in _run_raw_task
    self._prepare_and_execute_task_with_callbacks(context, task)
  File "/home/airflow/.local/lib/python3.6/site-packages/airflow/models/taskinstance.py", line 1283, in _prepare_and_execute_task_with_callbacks
    result = self._execute_task(context, task_copy)
  File "/home/airflow/.local/lib/python3.6/site-packages/airflow/models/taskinstance.py", line 1313, in _execute_task
    result = task_copy.execute(context=context)
  File "/home/airflow/.local/lib/python3.6/site-packages/airflow/operators/python.py", line 150, in execute
    return_value = self.execute_callable()
  File "/home/airflow/.local/lib/python3.6/site-packages/airflow/operators/python.py", line 161, in execute_callable
    return self.python_callable(*self.op_args, **self.op_kwargs)
  File "/opt/airflow/dags/create_tables_dag.py", line 19, in table_creator
    conn = psycopg2.connect(**conn_args)
  File "/home/airflow/.local/lib/python3.6/site-packages/psycopg2/__init__.py", line 122, in connect
    conn = _connect(dsn, connection_factory=connection_factory, **kwasync)
psycopg2.OperationalError: could not connect to server: Connection refused
	Is the server running on host "host.docker.internal" (127.0.0.1) and accepting
	TCP/IP connections on port 5432?

[2022-05-30 11:01:24,640] {taskinstance.py:1513} INFO - Marking task as UP_FOR_RETRY. dag_id=create_table_dag, task_id=create_tables, execution_date=20220530T110123, start_date=20220530T110124, end_date=20220530T110124
[2022-05-30 11:01:24,669] {local_task_job.py:151} INFO - Task exited with return code 1
[2022-05-30 11:01:24,684] {local_task_job.py:261} INFO - 0 downstream tasks scheduled from follow-on schedule check
